Workbook

Sheet HUCs Ordinances
A1: Ordinance Number | B1: Ordinance Description | C1: Full Text | D1: City | E1: E-Governance Index | F1: Overall CMCI Score
A2: AS OF 04-11-2024 | B2: PROPOSED AMENDMENTS "AN ORDINANCE ADOPTING THE REVISED PASAY CITY REVENUE CODE" | C2: Republic of the Philippines SANGGUNIANG PANLUNGSOD Pasay City Ordinance No.______, Series of 2024 AN ORDINANCE ADOPTING THE REVISED PASAY CITY REVENUE CODE Introduced by: Vice Mayor Waldetrudes S . Del Rosario Sponsored by: Councilor Mary Grace B. Santos Co-Sponsored by: Counci lors Mark Anthony A. Calixto, Marlon A. Pesebre, Ma. Antonia C. Cuneta, Abraham Albert Q. Alvina, Ricardo E. Santos, Jose C. Isidro, Jr., Editha Y. Manguerra, Donnabel M. Vendivel, Jennifer D. Panaligan, King Marlon A. Magat, Angelo Nicol P. Arceo, Julie G. Gonzales and Jose Miguel A. Mañez WHEREAS , Section 5, Article X of the 1987 Constitution provides that each local government unit shall have the power to create its own sources of revenues and to levy taxes, fees, and charges subject to such guidelines and limitations as the Congress may provide, consistent with the basic policy of local autonomy. Such taxes, fees, and charges shall accrue exclusively to the local governments ; WHEREAS , Section 129, Republic Act No. 7160, otherwise known as the Local Government Code of 1991, provinces, cities, and municipalities have the power to generate their sources of revenue. These local sources consist of: (a) tax revenues derived from real property tax, business tax, and other taxes; and (b) non- tax revenues derived from fees, charges, and receipts from the operation of economic enterprises in connection with the government’s exercise of its proprietary functions; WHEREAS , the main thrust of the C ity Government is for urban growth and progressive redistribution of wealth. It calls for a rational, more profitable , and fruitful endeavor to attain self- reliance, a consistent and practical delivery of services, the enforcement and effective prosecution of social, environmental , and economic development projects; WHEREAS , to ensure the maintenance, completion, promotion, and operation of the socio- economic development projects initiated by the C ity G overnment, it is highly imperative to maximize revenue collections of the C ity and its integrated development machinery; WHEREAS, to attain this objective, without unduly disturbing the initiative and growth of business, trade , and industry, the need for coordinating into one effective code all the revenue resources in the City Government becomes imperative; WHEREAS , on 15 November 1993, the City Council approved the latest revenue code of Pasay City with Ordinance No. 241 Series of 1993 entitled “An Ordinance Adopting the Pasay City Revenue Code .” WHEREAS , due to the ever -changing needs of the City and the continuous transformation of society, it is proper to update and revise the revenue code. NOW THEREFORE, BE IT ORDAINED as it is hereby ORDAINED by the Sangguniang Panlungsod in a session duly assembled: TITLE I. CHAPTER 1 GENERAL PROVISIONS Section 1. Title. – This City Ordinance shall be known as the “ 2024 Revised Pasay City Revenue Code”. Section 2. Scope. – This Code governs the administration, appraisal, assessment, levy, and collection of taxes, fees and charges in the City of Pasay. Section 3. Legal Basis. – This Code is enacted in accordance with the provisions of Republic Act 7160, otherwise known as the Local Government Code of 1991. Section 4. Fundamental Principles. – The following fundamental princip les govern the exercise of the C ity government's power of taxation and other revenue- raising powers: Page 2 of 137 Ordinance No. ______, Series 202 4 AN ORDINANCE ADOPTING THE 2024 REVISED PASAY CITY REVENUE CODE x------------------------------------x a) Taxation shall be uniform in each local government unit ; b) Taxes, fees, charges , and other impositions shall: 1. Be equitable and based as far as practicable on the taxpayer's ability to pay ; 2. Be levied and collected only for public purposes ; 3. Not be unjust, excessive, oppressive, or confiscatory ; 4. Not be contrary to law, public policy, national, economic policy or in restraint of trade. c) The collection of these local taxes, fees, charges, and other impositions shall in no case be let to any private persons; d) The revenue collected pursuant to the provisions of this Code shall inure solely to the benefit of, and subject to disposition by the City government, unless otherwise specifically provided in the Local Government Code; e) The C ity government shall evolve a progressive system of taxation. Section 5. Rules of Construction. – In constructing any provisions of this Code, the following rules of construction shall be observed unless inconsistent with the manifest intent of such provision. a) Words and Phrases – words and phrases shall be understood according to their common and approved usage. Words and phrases which may require a technical, peculiar , or appropriate meaning under this Code shall be constructed and understood according to such technical, peculiar, or appropriate meaning. b) Gender and Number – every word in this Code importing the masculine gender shall extend and apply to both males and females . Every word importing th e singular number shall extend and apply to one person or thing as well. Every word importing the plural number shall extend and apply to several persons or things as swell. c) Reasonable Time – in all cases where an action is required to be done within a reasonable time, the time shall be deemed to mean such period as may be necessary for the prompt performance of the act. d) Computation of Time – the time within which an act is to be done as provided in this Code or in any rule or regulation issued pursuant thereto when expressed in days shall be computed by excluding the first day and including the last day. If the last day falls on Sunday or a holiday, the same shall be excluded from the computation , and the day following shall be the last day. e) Conflicting Provisions of Sections – if the provisions of different sections in the same chapter conflict with each other, the provision of the sections which is last in point or sequence shall prevail. Section 6. Definition of Terms. – When used in this Code, the term: “Acquisition Cost ” for newly acquired machinery not yet depreciated and appraised within the year of its purchase, refers to the actual cost of the machinery to its present owner plus the cost of transportation handling and installation at the present site; “Actual Use ” refers to the purpose for which the property is principally or predominantly utilized by the person in possession thereof; “Ad Valorem Tax ” is a levy on real property determined on the basis of a fixed proportion of the value of the property; "Agricultural Products " includes the yield of the soil such as: corn, rice, wheat, rye, hay, coconuts, sugarcanes, tobaccos, root crops, vegetables, fruits, flowers and its by-products; ordinary salt; all kinds of fish; poultry; and livestock and animal products, whether in their original form or not. The phrase "whether in their original form or not" refers to the transformation of said products by the farmer, fisherman, produce r or owner through the application of processes to preserve or otherwise to pre pare said products for the market such as freezing, dyeing, salting, smoking, or stripping for purposes of preserving or otherwise preparing said products for the market. Page 3 of 137 Ordinance No. ______, Series 202 4 AN ORDINANCE ADOPTING THE 2024 REVISED PASAY CITY REVENUE CODE x------------------------------------x "Amusement " is a pleasurable diversion and entertainment. It is synonymous to relaxation, avocation, pastime, or fun; "Amusement Places " include theaters, cinemas, concert halls, and other places of amusement where one seeks admission to entertain oneself by seeing or viewing the show or performances; ''Business" means trade or commercial activity regularly engaged in as means of livelihood or with a view to profit; "Banks and Other Financial Institution" include non- bank financial intermediaries, lending investors, finance and companies, stock markets, stock brokers , and dealers in securities and foreign exchange, as defined under applicable laws or rules and regulations there under;s "Capital Investment " is the capital that the person employs in any undertaking or which he contributes to the capital of a partnership, corporation, or any other juridical entity or association in a particular taxing jurisdiction; "Charges " refer to pecuniary liability, as rents or fees against person s or property; “Contractor " includes persons, natural or juridical, not subject to professional tax under Section 1 01 of this Code, whose activity consists essentially of the sale of all kinds of services for a fee, regardless of whether or not the performance of the service calls for the exercise or use of the physical or mental faculties of such contractor or his employees. The term " contractor " shall include general engineering, general building and especially contractors as defined under applicable laws; filling, demolition and salvage works contractors; proprietors or operators of mine drilling apparatus; proprietors or operators of dockyards; persons engaged in the installation of water systems, and gas or electric light, heat, or power; proprietors or operators of smelting plants, engraving, plating, and plastic lamination establishments proprietors or operators of establ ishments for repairing, repainting, upholstering, washing or greasing of vehicles, heavy equipment, vulcanizing, recapping and battery charging; proprietors or operators of furniture shops and establishments of planning or surfacing and re- cutting of lumber, and sawmills under contract to saw or cut logs belonging to others; proprietor or operators of dry cleaning or dyeing establishments, steam laundries, and laundries using washing machines; proprietors or owners of shop for the repair of any kind of mechanical and electrical devices, instruments, apparatus, or furniture and shoe repairing by machine or any mechanical contrivance; proprietors or operators of establishments or lots for parking purposes; proprietors or operators of tailor shops, dress shops, milliners and hatters, beauty parlors, barber shops, massage clinics, sauna, Turkish and Swedish baths, slenderizing and building saloons, and similar establishments; photographic studios; funeral parlors; proprietors or operators of hotels, motels, and l odging houses; proprietors or operators of arrastre and stevedoring, warehousing or forwarding establishment s; master plumbers, smiths, and house and sign painters; printers, bookbinders, lightgraphers; publisher except those engaged in the publication and printing of any newspapers, magazine, review or bulletin which appears at regular intervals with fixed prices for subscription and sale and which is not devote d principally to the publication of advertisement; business agents, private detective or watchman agencies, commercial and immigration brokers, and cinematographic film owners, lessors and distributors. “Appraisal ” is the act or process of determining the value of property as of a specific date for a specific purpose; “Assessed Value ” is the fair market value of the real property multiplied by the assessment level. It is synonymous with taxable value; “Assessment ” is the act or process of determining the value of a property, or proportion thereof subject to tax, including the discovery, listing, classification, and appraisal of properties; “Assessment Level ” is the percentage applied to the fair market value to determine the taxable value of the property; “Commercial Land ” is land devoted principally to the object of profit and is not classified as agricultural, industrial, mineral, timber, or residential land . “Corporation” includes partnership, no matter how created or organized, joint-stock companies, joint accounts, associations , or insurance companies but does not include general professional partnerships and a joint venture Page 4 of 137 Ordinance No. ______, Series 202 4 AN ORDINANCE ADOPTING THE 2024 REVISED PASAY CITY REVENUE CODE x------------------------------------x or consortium formed to undertake construction projects or engage in petroleum, coal, geothermal, and other energy operations under an operating or consortium agreement under a service contract with the government. General professional partnerships are partnerships formed by the person for the sole purpose of exercising their common profession, no part of the income of which is derived from engaging in any trade or business; “Countryside and Barangay Business Enterprise " refers to any business entity, association, or cooperative registered under the provisions of Republic Act No. 6810, otherwise known as "Magna Carta for Countryside and Barangay Business Enterprise (Kalakalan20)"; "Dealer " means one whose business is to buy and sell merchandise, goods, and chattels as a merchant. He stands immediately between the producer or manufacturer and the consumer and depends for his profit not upon the labor he bestows upon his commodities but upon the skill and foresight with which he watches the market; “Depreciated Value ” is the value remaining after deducting depreciation from the acquisition cost; “Economic Life ” is the estimated period over which it is anticipated that machinery or equipment may be profitably utilized; “Fair Market Value ” is the price at which a property may be sold by a seller who is not compelled to sell and bought by a buyer who is not compelled to buy; "Fee" means a charge fixed by law or ordinance for the regulation or inspection of a business or activity. "Franchise " is a right or privilege, affected by the public interest which is conferred upon private persons or corporations, under such terms and conditions as the government and its political subdivisions may impose in the interest of public welfare, security, and safety; "Gross Sales or Receipts" include the total amount of the money or its equivalent representing the contract price, compensation, or service fee, including the amount charged or materials supplied with the services and deposits or advance payments actually or constructively received during the taxable quarte r for the services performed or to be performed for another person excluding discounts if determinable at the time of sales, sales return, excise tax, and value- added tax (VAT); “Manufacturing" includes every person who, by physical or chemical process, alters the exterior texture or form or inner substance of any raw material or manufactured or partially manufactured product in such manner as to prepare it for special use or uses to which it could have not been put in its original condition, or who by any such process, combines any such raw material or manufactured or partially manufactured products with other materials or products of the same or of different kinds and in such manner that the finished products of such process or manufacture can be put to a special use or uses to which such raw materials or manufactured or partially manufactured products in their original condition could have not been put, and who in addition, alter s such raw material or manufactured or partially manufactured products, or combines the same to produce such finished products for the purpose of their sale or distribution to others and not for his own use or consumption; “Improvement ” is a valuable addition made to a property or an amelioration in its condition, amounting to more than a mere repair or replacement of parts involving capital expenditures and labor which is intended to enhance its value, beauty or utility or to adopt it for new or other purposes; “Industrial Land” is land devoted principally to industrial activity as capital investment and is not classified as agricultural, commercial, timber, mineral, or residential land; “Machinery ” embraces machines, equipment, mechanical contrivances, instruments, appliances or apparatus which may not be attached, permanently or temporarily to the real property. It includes the physical facilities for production, the installations and appurtenant service facilities, those which are mobile, self -powered or self- propelled, and those not permanently attached to the real property which are actually, directly and exclusively used to meet the needs of the particular industry, business or activity and which their very nature and purpose are designed for, or necessary to its manufacturing, mining, logging, commercial, industrial or agricultural purposes; "Marginal Farmer or Fisherman” refers to an individual engaged in subsistence farming or fishing which shall be limited to the sale , barter or exchange of agricultural or marine products produced by himself and his immediate family; Page 5 of 137 Ordinance No. ______, Series 202 4 AN ORDINANCE ADOPTING THE 2024 REVISED PASAY CITY REVENUE CODE x------------------------------------x "Motor Vehicle " means ·any vehicle propelled by any power other than muscular power using the public roads, but excluding road rollers, trolley cars, street -sweepers, sprinklers, lawn mowers, bulldozers, graders, forklifts, amphibian trucks, and cranes if not used on public roads, vehicles which run only on rails or tracks, and tractors, trailers and traction engines of all kinds use delusively for agriculture purposes; "Municipal Waters " include not only streams, lakes and tidal waters within the municipality, not being the subject of private ownership and not comprised within the national parks, public forest, timber lands, forest reserves of fishery reserves, but also marine waters included between two lines drawn perpendicularly to the general coastline from points where boundar y lines of the municipality or C ity touch the sea at low tide and the third line parallel with the general coastline and fifteen (15) kilometers from it. Where two (2) municipalities are so situated on the opposite shores that there is less than fifteen (15) kilometers of marine waters between them, the third line shall be equally dista nt from opposite shores of the respective municipalities; "Operator " includes the owner, manager, administrator, or any other person who operates or is responsible for the operation of a business establishment or undertaking; "Peddler " means any person who, either for himself or on commission, travels from place to place and sell his goods or offer to sell and deliver the same. Whether a peddler is a wholesale peddler or a retail peddler of a particular commodity shall be determined from the definition of wholesale dealer or retail dealer as provided on this Title; "Person s" means every natural or juridical being, susceptible of right of obligations or of being the subject of legal relations; "Residents " refer to natural persons who have their habitual residence in the province, C ity, or municipality where they exercise their civil rights and fulfil their civil obligations, and to juridical persons to which the law or any other provision creating or recognizing them fixes their residence in a particular province, C ity or municipality. In the absence of such law, juridical persons are residents of the province, C ity or municipality where they have their legal residence or principal place of business or where they conduct their principal business or occupation. “Reassessment ” is the assigning of a new assessed values to property, particularly real estate, as the result of a general, partial or individual re-appraisal of the property; “Remaining Economic Life ” is the period of time expressed in years from the date of appraisal to the date when the machinery becomes valueless; “Remaining Values ” is the value corresponding to the remaining useful life of the machinery; “Replacement or Reproduction Cost ” is the cost that would be incurred on the basis of current prices in acquiring an equally desirable property or the cost of reproducing a new replica of the property on the basis of current prices with the same or closely similar materials; and “Residential Land ” is land principally devoted to habitation. "Retail" means a sale where the purchaser buys the commodity for his own consumption, irrespective of the quantity of the commodity sold; "Vessel” includes every type of boat, craft, or other artificial contrivance used, or capable of being used, as a means of transportation on water. "Wharfage " means a fee assessed against the cargo of a vessel engaged in foreign or domestic trade based on quantity, weight or measure received and/or discharged by vessel; and "Wholesale " means a sale where the purchaser buys or imports the commodities for resale to persons other than the end user regardless of the quantity of the transaction. Page 6 of 137 Ordinance No. ______, Series 202 4 AN ORDINANCE ADOPTING THE 2024 REVISED PASAY CITY REVENUE CODE x------------------------------------x CHAPTER 2 REAL PROPERTY TAX Section 7. Administration of Real Property Tax. – The City shall be primarily responsible for the proper, efficient, and effective administration of the real property tax subject to the rules and regulation issued by the Department of Finance. Accordingly, the Department of Finance and the City shall exercise the authority to review and continuously examine the property, assessment, and real property tax records to ensure the proper implementation of this rule and determine compliance with existing laws and regulations. Section 8. Appraisal of Real Property. – All real property , whether taxable or exempt, shall be appraised at the current and fair market value prevailing in the C ity. The Department of Finance shall promulgate the necessary rules and regulations for the classification, appraisal , and assessment of real property pursuant to the provisions of the Local Government Code of 1991. Section 9. Real Property Identification System. – All declarations of real property made under the provisions of this Title shall be kept and filed under a uniform classification system to be established by the City Assessor. Section 10. Declaration of Real Property by the Owner or A dministrator. – It shall be the duty of all persons, natural or juridical, owning or administering real property, including the im provements therein, within the C ity or their duly authorized representative, to prepare, or cause to be prepared and file with the City Assessor, a sworn statement declaring the true value of their real property, whether previously declared or undeclared, taxable or exempt, which shall be the current and fair market value of the property, as determined by the declarant. Such declaration shall contain a description of the property sufficient in detail to enable the City Assessor or his deputy to identify the same for assessment purpose. The sworn declaration of real property herein referred to shall be filed with the City Assessor once every three (3) years during the period from January first (1 st) to June thirtieth (30th) commencing with the calendar year 1994. Failure by the owner or his duly authorized representative to file the same will be penalized by a fine of ₱50.00 for the first month; ₱100.00 for the second month; ₱ 200.00 for the third month; ₱ 300.00 for the fourth month; ₱ 400.00 for the fifth month; ₱ 500.00 for the sixth month; and so on for a maximum of ₱ 5,000.00, the proceeds of which will be added to the funds of the City Assessor’s Office. Section 11. Duty of Person Acquiring Real Property or Making Improvement T hereon. – It shall be the duty of any person or his authorized representative, acquiring at any time real property in the city, or making any improvements on real property to prepare or caused to be prepared and filed with the City Assessor, a sworn statement declaring the true value of subject property, within sixty (60) days after the acquisition of such property or upon completion or occupancy of the improvement, whichever comes earlier. In case of machinery, the sixty (60) days period of filing the required sworn declaration of property values shall commence on the date of installation thereof as determined by the City Assessor, for this purposes, the City Asses sor may secure certification from the City Engineer or othe r appropriate officials of the C ity. Failure to comply will result to the penalties mentioned in the next succeeding Section. Section 12. Proof of Exemption from Real Property Taxation. – Every person by or for whom real property is declared, who shall claim tax exemption for such property shall file with the City Assessor within thirty (30) days from the date of the declaration of real property sufficient documentary evidence in support of such claim including corporate charters, title of ownership, articles of incorporation, by laws, contracts, affidavits, certification and mortgage deeds, contracts, affidavits, certifications and mortgage deeds and similar documents. If the required evidence is not submitted within the period herein prescribed the property shall be listed as taxable in the Assessment Roll. However, if the property shall be proven to be exempt, the same shall be dropped from the Assessment Roll. Section 13. Dut y of the Registrar of Deeds to Appraise Assessor of Real Property Listed in R egistry. – a) Within six (6) months from the date of effectivity of the code, and/or before June 30 th of every year thereafter, the Registrar of Deeds shall prepare and submit to the City Assessor the abstract of his Registry of Property which shall include a brief but sufficient description of real properties entered therein, their Page 7 of 137 Ordinance No. ______, Series 202 4 AN ORDINANCE ADOPTING THE 2024 REVISED PASAY CITY REVENUE CODE x------------------------------------x present owners, and the date of their most recent transfer or alienation accompanied by copies of corresponding deed of sale, donation or partition or other form of alienation. b) Before any documents of transfer, alienation, or encumbrance of real property may be registered, the Registrar of Deeds shall require the presentation of a certificate or clearance issued by the City Treasurer to the effect that all current year and past year basic and additional SEF real property taxes, and the tax on transfer of real property ownership due on the subject, have been paid in full including interest or penalties due hereon. Failure to provide such certification shall be a valid cause for the Registrar of Deeds to refuse the registration of the documents. Without such certification or tax clearance, the registration is null and void. c) The Registrar of Deeds and notaries public shall furnish the City Assessor with copies of contracts, selling, transferring or otherwise conveying, leasing, or mortgaging real property registered by or acknowledged before them within thirty (30) days from the date of registration acknowledgment. Section 14. Duty of Official I ssuing Building Permit or Certificate of Registration of Machinery to Transmit Copy to A ssessor. – Any public official or employee who may now or hereafter be required by law or regulation to issue to any person a permit for the construction, addition, repair, or renovation of a building, or permanent improvement on land, or a certificate of registration for any machinery including machines, mechanical machine contrivances and app aratus attached or fixed on land or to another real property shall transmit within thirty (30) days of its issuance to the City Assessor. Section 15. Duty of Geodetic Engineer to F urnish Copy of the P lans to City Assessor. – It shall be the duty of all geodetic engineers, private or public, to furnish free of charge the City Assessor a white or blue print copy of each of all approved original or subdivision plans or maps of surveys executed by them within thirty (30) days from receipt of such plans from the Land Management Bureau, the Land Registration Authority, or the Housing and Land Use Regulatory Board, as the case may be. Section 16. Preparation of S chedule of Fair Market Value. – Before any general revision of property assessment is made pursuant to the provisions of this Code, there shall be prepared a schedule of fair market values by the City Assessor for the different classes of real property situated in the City for enactment by ordinance of the City Council. The schedule of fair market values shall be published in a newspaper of general circulation or in the absence thereof, shall be posted in the City Hall and in two (2) other conspicuous places in the City. Section 17. Classes of Real Property for Assessment Purposes. – For purposes of assessment, real properties shall be classified as residential, agricultural, commercial, industrial or special. Section 18. Special C lasses of Real Property. – All lands, buildings, and any improvements thereon actually directly and exclusively used for hospitals, cultural or scientific purposes, those owned and used by local water districts and government owned and controlled corporation rendering essential public services in the supply and distribution of water and/or generation of electric power shall be classified as special. Section 19. Actual U se of Real Property as Basis for Assessment. – Real property shall be classified, valued, and assessed on the basis of its actual use regardless of where located, whoever owns it, and whoever uses it. Section 20. Imposition of the B asic Real Property Tax. – There is hereby levied an annual ad valorem tax on the assessed value of real property such as land, building, machinery and the improvements affixed or attached to real property located in the City of Pasay at the following rates: CLASSES OF PROPERTY RATES OF LEVY Residential 1.5% Commercial 2% Industrial 2% Special 2% Section 21. Additional L evy on Real Property for the Special Education Fund (SEF). – There is hereby levied an annual tax of one percent (1%) on the assessed value of real property which shall be in addition to the basic real property tax. The proceeds thereof shall exclusively accrue to the Special Education Fund (SEF). Page 8 of 137 Ordinance No. ______, Series 202 4 AN ORDINANCE ADOPTING THE 2024 REVISED PASAY CITY REVENUE CODE x------------------------------------x All real property taxes which are not paid on time shall be subjected to a two percent (2%) penalty per month of unpaid amount of a fraction thereof until the date of delinquency until such taxes are fully paid. Provided, however, that in no case shall the total interest on the unpaid tax or portion thereof exceed thirty -six (36) months. Section 22. Valuation of Real Property. – In cases where (a) real property is declared and listed for taxation purposes for the first time; (b) there is an on -going general revision of property classification and assessment; (c) a request is made by the person in whose name the property is declared, the City Assessor or his duly authorized deputy shall, in accordance with the provisions of this chapter, make a classification, appraisal, and assessment of the real property listed and described in the declaration irrespective of any previous assessment or taxpayer’s valuation thereon. PROVIDED, however, that the assessment of real property shall not be increased often or more than once every three (3) years except in case of new improvements substantially increasing the value of said property or any change in its actual use. Section 23. Date of Ef fectivity of A ssessment or Re-assessment. – All assessment or re -assessment made after the first (1 st) day of any year shall take effect on the first (1st) day of January of the succeeding year. PROVIDED, however, that the re -assessment of real property due to its partial or total destruction, or to a major change in its actual use, or to any great sudden inflation or deflation of real property values, or to the gross illegality of the assessment when made or any other abnormal c | D2: Pasay | E2: 0.47402597 | F2: 56.7826
A3: 989 | B3: AN ORDINANCE PROVIDING FOR THE MODE AND AMOUNT OF PAYMENT FOR BUSINESS PLATE NUMBER REQUIREMENT OF ALL BUSINESS ESTABLISHMENTS IN PASAY CITY AS PER ORDINANCE NO. 977, SERIES OF 1997 WHICH REQUIRES ALL BUSINESS ESTABLISHMENTS AND OCCUPATIONAL UNDERTAKINGS TO REGISTER AND SECURE A BUSINESS PERMIT REGISTRATION PLATE BEFORE STARTING A BUSINESS IN THE CITY. | C3: a Mite’ a VAaw, — @ a, REPUBLIC OF THE PHILIPPINES OFFICE OF THE SANGGUNIANG PANLUNGSOD PASAY CITY, METRO MANILA ORDINANCE NO. 2389 1998 AN ORDINANCE PROVIDING FOR THE MODE AND AMOUNT OF PAYMENT FOR BUSINESS PLATE NUMBER REQUIREMENT OF ALL BUSINESS ESTABLISHMENTS IN PASAY CITY AS PER ORDINANCE NO. 977, SERIES OF WHICH REQUIRES ALL BUSINESS ESTABLISHMENTS AND OCCUPATIONAL UNDERTAKINGS TO REGISTER AND SECURE A BUSINESS PERMIT REGISTRATION PLATE BEFORE STARTING A BUSINESS IN THE 1997 CITY. SPONSORED BY: ACTING VICE MAYOR GREG F. ALCERA, COUNCILORS ROBERTO L. ALVAREZ AND EDITA V. VERGEL DE DIOS WHEREAS, there is a need to classify and stratify the amounts to be paid in | ; securing business permit registration plate depending upon the nature of business activity \|/. conducted in the City of Pasay. NOW THEREFORE, BE IT ORDAINED AS IT IS HEREBY ORDAINED, / \ by the Sangguniang Panlungsod of Pasay in session duly assembled to provide as it hereby _ provides the following schedule of assessments of payments that is to be enforced as the mode and amount of payments for the business license plate over and above other assessments for annual municipal licenses, to wit: A. FIRSTCLASS HOTELS -~____..................... NIGHT CLUBS, FIRST CLASS KARAOKE SAUNA BATH, BUS TERMINAL, ETC. B. MOTELS, BANKS —=ECL_..ny....... . cee eee TRAVEL AGENCY, RECRUITMENT AGENCY, PLACEMENT AND PROMOTION C. BEER HOUSE, MUSIC LOUNGE ___........... VIDEOKE, PAWNSHOP, RESTAURANT, MANUFACTURER, MONEY CHANGER, ETC. D. IMPORTER, EXPORTER, SERVICES __................. GEN. MERCHANIDISE, REAL ESTATE LESSOR, BOARDING HOUSE, TAILOR SHOP, DRESS SHOP, BARBER SHOP, HOT PANDESAL, PHOTO STUDIO, SECURITY, ETC. E. SARI-SARI STORE, CARENDERIA __............. REFRESHMENT STAND, LESSOR, ETC. Nineteen Hundred and Ninety-Eight. ENACTED, in Pasay City, this 12t'ay of January in the Year of Our Lord , REG K ALCERA WENCESLAO B. TRINIDAD APPROVED: HO Acting City Mayor Acting Vi P 3,000.00 2,000.00 1,000.00 500.00 300.00 6 ¢ Presiding Officer -page 2- Ordinance providing for the mode and amount of payment for business plate number requirement for all business establishments in Pasay City. 1. HON. ANTONINO G. CALIXTO 2. HON. EMMANUEL M. IBAY 3. HON. JUSTO C. JUSTO 4. HON. ROMULO M. CABRERA 5. HON. REYNALDO O. PADUA 6. HON. ROBERTO L. ALVAREZ 7. HON. EDITA V. VERGEL DE DIOS 8. HON. ULDARICO C. ARABIA 9. HON. ALBERTO V. PAREDES 10. HON. EDUARDO I. ADVINCULA 11. HON. TEQDULO R. LORCA 12. HON. GENEROSO F. CUNETA 13. HON. LEVINE A. CUNETA ATTESTED: | D3: Pasay | E3: 0.47402597 | F3: 56.7826
A4: 987 | B4: AN ORDINANCE PROVIDING FOR THE ADMINISTRATIVE SUPPORT SERVICES TO THE OFFICE OF SENIOR CITIZENS (OSCA) AND PROVIDING FUNDS THEREFORE. | C4: 1) REPUBLIC OF THE PHILIPPINES OFFICE OF THE PASAY CITY COUNCIL ORDINANCE NO. _98_7_ S-1998; ' AN ORDINANCE PROVIDING FOR THE ADMINISTRATIVE SUPPORT SERVICES TO THE OFFICE OF SENIOR CITIZENS (OSCA) AND PROVIDING FUNDS THEREFORE. Sponsored by Councilor Greg F. A/cera WHEREAS, Republic Act 7432 mandates the maximization of the contribution of Senior Citizens to society, and grants them special privileges and benefits, and the DILG Memo Circular No. 93-177 addressed to all local government units providing policy directions for the effective implementation ofRA7432 has already been effected; WHEREAS, Pasay City Ordinance No. 191 S-1993 has effected special privileges and the necessary framework to implement and effect RA 7432; WHEREAS, there is a need to preserve whatever gains was had in the organization of various Senior Citizen's groups in Pasay City, and ensure the delivery of basic services and privileges as mandated by law; NOW THEREFORE BE IT ORDAINED BY THE PASAY CITY COUNCIL IN A SESSION DULY ASSEMBLED THAT; 1.The Administrative Secretariat m1der the Office of Councilor Greg F. Alcera be maintained, and a majority of its personnel be manned by registered Pasay OSCA members; 2. The amount of PI43,000.00 be appropriated for the salaries and allowances of personnel to be designated to man the OSCA Office effective February -December, 1998. 3. The amount of P50,000.00 be appropriated for the purchase and/or printing of necessary documents and office supplies; 4.That the above-mentioned amounts be taken from the Special Projects Fund of the Office of the City Mayor and/or the proponent. APPROVED THIS 13th DAY OFJ am1.ary , 1998. �� HON. WENCESLAO TRINIDAD ACTING CITY MAYOR HON. GREG F. ALCERA HON. ANTONINO G. CALIXTO HON. EMMANUEL M. IBAY HON. JUSTO C. JUSTO HON. ROMULO M. CABRERA HON. REYNALDO 0. PADUA HON. ROBERTO L. ALVAREZ HON. EDITA VERGEL DEDIOS HON. ULDARICO C. ARABIA HON. ALBERTO V. PAREDES HON. EDUARDO I. ADVINCULA HON. TEODULO R. LORCA JR. HON. GENEROSOF.CUNETA HON. LEVINE CUNETA ATTESTED BY �: ___,,....., 0 .YAM SEC Y , .,, | D4: Pasay | E4: 0.47402597 | F4: 56.7826
A5: 986 | B5: ORDINANCE MANDATING THE OFFICE OF THE CITY ACCOUNTANT AND CITY TREASURER TO DEVIDE THE INTERNAL REVENUE ALLOTMENT (IRA) OF BARANGAY 183 ZONE 20 AND ALLOCATE A PORTION THEREOF TO BARANGAY 201, ZONE 20, PASAY CITY IN ACCORDANCE WITH NUMBER OF POPULATION OF SAID BARANGAYS | C5: 8 couc OF THE omen SANGGUNIANG PANLUNGSOD PASAY CITY ORDINANCE NO. 986 _,S. 1998 ORDINANCE MANDATING THE OFFICE OF THE CITY ACCOUNTANT AND CITY TREASURER TO DEVIDE THE INTERNAL REVENUE ALLOTMENT (IRA) OF BARANGAY 183, ZONE 20 AND ALLOCATE A PORTION THEREOF TO BARANGAY 201, ZONE 20, PASAY CITY IN ACCORDANCE WITH NUMBER OF 3 POPULATION OF SAID BARANGAYS. ) Sponsored by: Acting Vice Mayor GREG F. ALCERA and Councilors ROMULO M. CABRERA, EDITA V. VERGEL DE DIOS, ANTONINO G. CALIXTO, ULDARICO C. ARABIA, REYNALDO O. PADUA, JUSTO C. JUSTO, TEODULO R. LORCA, JR. ROBERTO L. ALVAREZ, EMMANUEL M. IBAY, EDUARDO I. ADVINCULA, , ALBERTO B. PAREDES, GENEROSO F. CUNETA and LEVINE A. CUNETA WHEREAS, pursuant to Ordinance No. 831, S. 1997, the areas of Teachers Bliss, Kalayaan Village and Balagbag was segregated from barangay 183 and Barangay 201 was created out of the said segregated areas; WHEREAS, the Internal Revenue Allotment of Barangay 183 for the year 1998 is * = computed at FOUR MILLION EIGHT HUNDRED TWENTY THOUSAND SIX S HUNDRED THIRTY EIGHT (P4,820,638.00) PESOS which allotment includes the share of Barangay 201; WHEREAS, the number of population of Barangay 201 as per Census of September 1, 1995 is ELEVEN THOUSAND THREE HUNDRED EIGHTY FIVE (11,385) inhabitants _. while that of Barangay 183 is THIRTY FOUR THOUSAND THREE HUNDRED FORTY EIGHT (34,348) inhabitants; WHEREAS, there is a need for the Office of the City Treasurer to devide the Internal Revenue Allotment of Barangay 183 and allot a portion thereof to Barangay 201 in accordance with their respective number of population. NOW THEREFORE, be it ORDAINED, as it is hereby ORDAINED, in session duly ~\ assembled that: SECTION 1- COMPUTATION OF INTERNAL REVENUE ALLOTMENT (IRA)- The Office of the City Accountant and City Treasurer are hereby mandated to devide the IRA of Barangay 183 and allot a portion thereof to Barangay 201 computed in accordance “——LArwith their respective number of population to wit: NO. OF POPULATION 1998 IRA SHARE BARANGAY 183 34,348 Inhabitants P3,620,565.00 BARANGAY 201 11,385 Inhabitants P1,200,073.00 - which Internal Revenue Allotment (IRA) is to be released every quarter to said Barangays; SECTION 2- EFFECTIVITY- This Ordinance shall take effect upon its approval and publication in a newspaper of general circulation in Pasay City; ENACTED in the City of Pasay this 6th day of aay in the Year of Our Lord Nineteen Hundred and Ninety Eight. oR eae HON. WENCESLAO B. TRINIDAD Acting City Mayor Ac fLON. GREG\F. ALCERA ng Vice Mayor & Presiding Officer -Page 2- 8 : 5 (Ordinance No. _, S. 1998) 1. Hon. ANTONINO G. CALIX = 2. Hon. EMMANUEL M. IBAY Scan 2S 3. Hon. JUSTO C. JUSTO YA 4. Hon. ROMULO M. CABRERA <fs f Vege 5. Hon. REYNALDO O. PADUA We e 6. Hon. ROBERTO L. ALVAREZ Ohl 7. Hon. EDITA V. VERGEL DE DIOS Z/ L Prod 8. Hon. ULDRICO C. ARABIA 9. Hon, ALBERTO V. PAREDES 10. Hon. EDUARDO I. ADVINCULA 11. Hon. TEODULO R. LORCA, 12. Hon. GENEROSO F. CUNETA 13. Hon. LEVINE A. CUNETA ATTESTED BY: ATTX. ROBER YO B. YAM City Sécfetary REPUBLIC OF THE PHILIPPINES SANGGUNIANG PANLUNGSOD _ PASAY CITY ORDINANCE NO.984, $-1997, = AN ORDINANCE FURTHER AMENDING ORDINANCE NO. 267, S-1994 DECLARING VERGEL STREET FROM TRAMO STREET TO TAFT AVENUE FROM 6:00 A.M. TO 6:00 P.M. AS NO PARKING ON BOTH SIDES. Sponsored by: Councilors Romulo M. C C. Arabia and Antonino G. Calixto abrera, Edita V. Vergel de Dios, Uldarico WHEREAS, Barangays 98 and 99, Zone 14, Pasay City passed resolution seeking to declare Vergel Street from Tramo Street to Taft Avenue as no parking on both sides from 6:00 A.M. to 8:00 P.M.; WHEREAS, the COMMITTEE ON TRANSPORTATION recommeded to the SANGGUNIANG PANLUNGSOD to amend Ordinance No. 267, S-1994 to declare the entire length of Vergel Street in the provisio of NO PARKING ON BOTH SIDES, NOW THEREFORE , BE IT RESOLVED AS IT IS HEREBY RESOLVED in session duly assembled that: SECTION L Section 6.25 of Ordinance No. 267, S-1994 is hereby amended to ‘read as follows: . “SECTION 6.25 - Vergel Street from Cabrera Street to Taft Avenue from 6:00 A.M. to 8:00 P.M.” SECTION 2, EFFECTIVITY - This Ordinance shall take effect upon its approval and publication ina newspaper of general circulation in Pasay City. DONE in the City of Pasay this 16th day of December in the Year of Our Lord Nineteen Hundred and Ninety Seven. APPROVED: ‘ ‘A HON. WENCESLAO B. TRINIDAD Acting City Mayor A. HON. ANTONINO G.CALIXTO 2. HON. EMMANUEL M. IBAY PAGE 2 of Ordinance No 984,S1997 Ordinance further amending Ordinance No 267, S-994 declaning Verge! Street From Tramo Sueetto Taf Avenue from 600 A.M. to800PM asno parking on both sides 3. HON. JUSTO C. JUSTO 4. HON. REYNALDO O. PADUA 5. HON. ROMULO M. CABRERA | 6. HON. ROBERTO L. ALVAREZ 4 HON. EDITA V.VERGEL DE DIOS 8. HON. ULDARICO C. ARABIA 2: HON. ALBERTO V. PAREDES : 10. HON. EDUARDO L ADVINCULA _ Il. HON. TEODULO R. LORCA JR. 12. HON. GENEROSO F. CUNETA 13. HON. LEVINE A. CUNETA “,0VED ORDINANCE - ) ASAY ‘8. Hon. ULDRICO C. ARABIA ALPPA TIMES ~ Jan. 22-31, 1998 SANGGUNIANG PANLUNGSOD PASAY. CITY ORDINANCE NO. 986_, S. 1998 E DATING THE OFFICE OF THE CITY ACCOUNTANT AND CITY TREASURER TO DEVIDE THE INTERNAL REVENUE ALLOTMENT (IRA) OF BARANGAY 183, ZONE 20 AND ALLOCATE A PORTION THEREOF TO BARANGAY 201, ZONE 20, PASAY CITY IN ACCORDANCE WITH NUMBER OF POPULATION OF SAID BARANGAYS. ? Sponsored by: Acting Vice Mayor GREG F. ALCERA and Councilors ROMULO M. CABRERA. EDITA v. VERGEL DE DIOS, ANTONINO G. CALIXTO, ULDARICO C. ARABIA, REYNALDO O. PADUA, JUSTO C. JUSTO, TEODULO R. LORCA, JR. ROBERTO L. ALVAREZ, EMMANUEL M. IBAY, EDUARDO I. ADVINCULA, , ALBERTO B. PAREDES, GENEROSO F: CUNETA and LEVINE A. CUNETA WHEREAS, pursuant to Ordinance No. 831, S. 1997, the areas of Teachers Bliss, Kalayaan Village and’ Balagbag was sceregatcd from barangay 183 and Barangay 20! was created out of the said segregated areas; WHEREAS, the Internal Revenue Allotment of Barangay. 183 for the year 1998 is computed at FOUR MILLION EIGHT HUNDRED TWENTY THOUSAND SIX HUNDRED THIRTY EIGHT (P4,820,638.00) PESOS which allotment includes the share of Barangay 201; WHEREAS, the number of population of Barangay 20) as per ier of September 1, 1995 is ELEVEN THOUSAND THREE HUNDRED EIGHTY FIVE (11,385) ‘inhabitants while that of Barangay 183 is THIRTY FOUR THOUSAND THREE HUND D FORTY EIGHT (34,348) inhabitants; WHEREAS, there is a need for the Office of the City Treasurer to devide the Internal Revenue Allotment of Barangay 183 and allot a portion thereof to Barangay 201 in accordance with their réspective number of population. NOW THEREFORE, be it ORDAINED, as it is hereby ORDAINED, in session duly assembled that: SECTION 1- COMPUTATION OF INTERNAL REVENUE ALLOTMENT (IRA)- The Office of the City Accountant and City Treasurer are hereby mandated to devide the IRA of Barangay 183 and allot a portion thereof to Barangay 201 computed in accordance with their respective number of population to wit: : NO. OF POPULATION 1998 IRA SHARE BARANGAY 183 34,348 Inhabitants P3,620,565.00 BARANGAY 20! 11,385 Inhabitants P1,200,073.00 which Internal Revenue Allotment (IRA) is to be released every quarter to said Barangays; SECTION 2- EFFECTIVITY- This Ordinance shall take effect upon its approval and publication in a newspaper of general circulation in Pasay City; ENACTED in the City of Pasay this 6th day of January-in the Year of Our Lord Nineteen Hundred and Ninety Eight. APPROVED: » HON. WENCESLAO B. TRINIDAD Acting City Mayor Act *- 1. Hon. ANTONINO G. CALI 2. Hon. EMMANUEL M. IBAY 3. Hon. JUSTO C. JUSTO 4. Hon. ROMULO M. CABRERA _ 5, Hon. REYNALDO O. PADUA 6. Hon. ROBERTO L, ALVAREZ 7. Hon. EDITA V. VERGEL DE DIOS 9. Hon. ALBERTO V. PAREDES 10. Hon. EDUARDO I. ADVINCULA II. Hon. TEODULO R. LORCA, 12. Hon. GENEROSO F. CUNETA _ 13. Hon. LEVINE A. CUNETA ATTESTED BY: ATTX. ROBE B. YAM City Sdefetary | D5: Pasay | E5: 0.47402597 | F5: 56.7826
A6: 984 | B6: AN ORDINANCE FURTHER AMENDING ORDINANCE NO. 267, S-1994 DECLARING VERGEL STREET FROM TRAMO STREET TO TAFT AVENUE FROM 6:00 AM TO 6:00 PM AS NO PARKING ON BOTH SIDES. | C6: REPUBLIC OF THE PHILIPPINES SANGGUNIANG PANLUNGSOD PASAY CITY ORDINANCE NO.984, S-1997 ORDINANCE FURTHER AMENDING ORDINANCE NO. 267, S-1994 DECLARING VERGEL STREET FROM TRAMO STREET TO TAFT AVENUE FROM 6:00 AJM. TO 6:00 PJVL AS NO PARKING ON BOTH SIDES. Sponsored by: Councilors Romulo M. Cabrera, Edita V. Vergel de Dios, Uldarico C. Arabia and Antonino G. Calixto WHEREAS, Barangays 98 and 99, Zone 14, Pasay City passed resolution seeking to declare Vergel Street from Tramo Street to Taft Avenue as no parking on both sides from 6:00 AM . to 8:00 P.M.; WHEREAS, the COMMITTEE ON TRANSPORTATION recommeded to the SANGGUNIANG PANLUNGSOD to amend Ordinance No. 267, S-1994 to declare the entire length of Vergel Street in the provisio of NO PARKING ON BOTH SIDES; NOW THEREFORE , BE IT RESOLVED AS IT IS HEREBY RESOLVED in session duly assembled that: SECTION 1 . Section 6.25 of Ordinance No. 267, S-1994 is hereby amended to read as follows: “SECTION 6.25 - Vergel Street from Cabrera Street to Taft Avenue from 6:00 AM . to 8:00 P.M.” SECTION 2. EFFECTIVITY - This Ordinance shall take effect upon its approval and publication in a newspaper of general circulation in Pasay City. DONE in the City of Pasay this 16th day of December in the Year of Our Lord Nineteen Hundred and Ninety Seven. APPROVED: [ON. WENCESLAO B. TRINIDADActing City Mayor>N . GREG W. ALCERA Actji Vice-Mayor'# Presiding Officer 2.HON. ANTONINO G.CAUXTO HON. EMMANUEL M. IBAY PAGE 2 of Ordinance No. 984, S-1997 Ordinance further amending Ordinance No. 267, S-1994 declaring Verge! Street From Tramo Street to Taft Avenue from 6:00 A M . to 8:00 P M. as no parking on both sides. 3. 4. 5. 6. 7. 8. 9.HON. JUSTO C. JUSTO HON. REYNALDO O. PADUA HON. ROMULO M. CABRERA HON. ROBERTO L. ALVAREZ ATTESTED: | D6: Pasay | E6: 0.47402597 | F6: 56.7826
A7: 981 | B7: AN ORDINANCE EXTENDING THE DEADLINE OF DECEMBER 31, 1997 FOR THE PAYMENT OF LAND TAX FOR THE YEAR 1997 AND ,THE DEADLINE OF JANUARY 20, 1998 FOR THE PAYMENT OF BUSINESS LICENSES, BOTH, TO JANUARY 31, 1998. | C7: ® REPUBLIC OF THE PHILIPPINES OFFICE OF THE SANGGUNIANG PANLUNGSOD PASAY CITY, METRO MANILA SA ORDINANCE NO. 981 - S 1997 IN AN ORDINANCE EXTENDING THE DEADLINE OF DECEMBER 31, 1997 FOR THE PAYMENT OF LAND TAX FOR THE YEAR 1997 AND THE DEADLINE OF ¢ JANUARY 20, 1998 FOR THE PAYMENT OF BUSINESS LICENSES, BOTH, TO ; JANUARY 31, 1998. \ Sponsored by: Acting Vice Mayor GREG F. ALCERA, Councilors ANTONINO G. CALIXTO, EMMANUEL M. IBAY, JUSTO C. JUSTO, ROMULO M. CABRERA, REYNALDO O. PADUA, ROBERTO L. ALVAREZ, EDITA V. VERGEL DE DIOS, ULDARICO C. ARABIA, ALBERTO V. PAREDES, EDUARDO I. ADVINCULA, \|__TEODULO R. LORCA JR., GENEROSO F. CUNETA and LEVINE A. CUNETA WHEREAS, Section 167 of the Local Government Code of 199] provides that a local government unit 1s expressly authorized to either extend the deadline for the payment of local taxes or even waive the payment of interest, surcharges, or penalties on delinquent fn taxes; - i WHEREAS, for the year 1997, considering that there is still a substantial number ING of taxpayers who has not yet paid their corresponding real property tax and who may opt Ry to pay the same on the last day of the current year, but would unable to do so because of so many legal holidays during the month of December 1997, it would be for the benefits of the taxpayers if the deadline for the real property tax and business licenses be extended to January 31, 1998. . 3 N NOW, THEREFORE, BE IT ORDAINED BY THE PASAY CITY 1 COUNCIL IN SESSION DULY ASSEMBLED THAT; | i Section 1. Extension of Deadline for the Payment of Local Taxes and ‘ie Licenses - The payment of land tax corresponding to the Year 1997 which will expire on December 31, 1997 is hereby extended up to January 31, 1998 and the payment of business licenses which will expire on January 20, 1998 is hereby extended up to January 31, 1998. + Section 2. Effectivity - This ordinance shall take effect upon passage and (}\ approval of the Sangguniang Panlungsod, approval of the City Mayor and its publication oS in a newspaper of general circulation in the city. Fa ENACTED in Pasay City, this 12" day of December in the Year of Our Lord, / _|Nineteen Hundred and Ninety-Seven. ¥ 4 y , APPROVED: Laney a HON. WENCESLAO B. TRINIDAD By. Acting City Mayor -page 2- Ordinance 981 Series of 1997 1. HON. ANTONINO G. CALIXTO 2. HON. EMMANUEL M. IBAY 3. HON. JUSTO C. JUSTO 4. HON. ROMULO M. CABRERA 5. HON. REYNALDO O. PADUA 6. HON. ROBERTO L.. ALVAREZ 7. HON. EDITA V. VERGEL DE DIOS 8. HON. ULDARICO C. ARABIA 9: HON. ALBERTO V. PAREDES 10. HON. EDUARDO I. ADVINCULA 11. HON. TEODULO R. LORCA 12. HON. GENEROSO F. CUNETA 13. HON. LEVINE A. CUNETA ATTESTED: ATTY. ROBERTO B. YAM City Secretary ra | D7: Pasay | E7: 0.47402597 | F7: 56.7826
A8: 980 | B8: AN ORDINANCE APPROPRIATING THE AMOUNT OF TWENTY THOUSAND PESOS (P20,000.00) AS FINANCIAL ASSISTANCE TO THE HEIRS OF BARANGAY TANOD GONZALO LUCERIO OF BARANGAY 26, PASAY CITY WHO DIED IN LINE OF DUTY. | C8: A } REPUBLIC OF THE PHILIPPINES SANGGUNIANG PANLUNGSOD PASAY CITY, METRO MANILA ORDINANCE NO. 980 S-1997 INANCE APPROPRIATING THE AMOUNT OF TWENTY THOUSAND (P20,000.00) AS FINANCIAL ASSISTANCE TO THE HEIRS OF RANGAY TANOD GONZALO LUCARIO OF BARANGAY 26, PASAY CITY, WHO DIED IN LINE OF DUTY. Sponsored by: Acting Vice Mayor GREG F. ALCERA, Councilors ANTONINO G. CALIXTO, ROMULO M. CABRERA, EMMANUEL M. IBAY, REYNALDO O. PADUA, JUSTO C. JUSTO, ROBERTO L. ALVAREZ, EDITA V. VERGEL DE DIOS, ULDARICO C. ARABIA, ALBERTO V. PAREDES, EDUARDO I. ADVINCULA,, TEODULO R. LORCA, JR., GENEROSO F. CUNETA and LEVINE A. CUNETA. WHEREAS, Gonzalo Lucario of Barangay 26, Pasay City, is a Barangay Tanod, who died while in the performance of his duty; WHEREAS, the heirs of the said barangay tanod was left to shoulder and defray the expenses incurred from the untimely death of the mentioned tanod who just responded to the call of duty as a barangay official; WHEREAS, the death of Gonzalo Lucario 1s a great loss to the family and to the barangay. NOW THEREFORE BE IT ORDAINED AS IT IS HEREBY ORDAINED, by the Sangguniang Panlungsod of Pasay in session duly assembled to appropriate as it hereby appropriates the amount of Twenty Thousand Pesos (P20,000.00) as financial assistance to the heirs of Barangay Tanod Gonzalo Lucario of Barangay 26, Pasay City. ENACTED in Pasay City, this 9" day of December, in the Year of Our Lord Nineteen Hundred and Ninety-Seven. APPROVED: ATTY. WENCESLAO B. TRINIDAD Acting City Mayor 7, ALCERA & Presiding Officer 1. HON. ANTONINO G. CALIXTO 2. HON. EMMANUEL M. IBAY 3. HON. JUSTO C. JUSTO -page 2- ORD. No. 980 Series of 1997 10. 11. LZ. HON. ROMULO M. CABRERA . HON. REYNALDO O. PADUA HON. ROBERTO L. ALVAREZ HON. EDITA V. VERGEL DE DIOS HON. ULDARICO C. ARABIA HON. ALBERTO V. PAREDES HON. EDUARDO I. ADVINCULA HON. TEODULO R. LORCA, JR. HON. GENEROSO F. CUNETA . HON. LEVINE A. CUNETA ATTESTED BY: —- ATTY. ROBERTO B. YAM City Secretary Wi | D8: Pasay | E8: 0.47402597 | F8: 56.7826
A9: 978 | B9: ORDINANCE ENACTING RULES AND REGULATIONS IN THE PAYMENT OF ALLOWANCES TO POLICE OFFICERS AND PERSONNEL'S ASSIGNED IN PASAY CITY | C9: O05 LIC OF THE pETLIPPra SANGGUNIANG PANLUNGSOD PASAY CITY r | ORDINANCE NO. 978; S. 1997 } | v ORDINANCE ENACTING RULES AND REGULATIONS IN THE . PAYMENT OF ALLOWANC TO POLICE OFFICERS AND \ PERSONNEL’S ASSIGNED IN PASAY CITY Sponsored by: Acting Vice Mayor GREG F, ALCERA, Councilors ROMULO M. CABRERA. ANTONINO G. CALIXTO, ULDARICO C. ARABIA, JUSTO C. JUSTO, EDUARDO I. ADVINCULA, REYNALDO O. PADUA, EMMANUEL M. IBAY, ROBERTO L. ALVAREZ, LEVINE A. CUNETA, GENEROSO F. CUNETA, EDITH V. VERGEL DE DIOS, ALBERTO V.PAREDES and TEODULO R. LORCA. WHEREAS, the City Mayor is vested with operational supervision and control over police units assigned in Pasay City; WHEREAS, the SANGGUNIANG PANLUNGSOD has enacted Resolution No. 945, S-1997, strongly requesting the Philippine National Police (PNP) Regional Directorate to assign and deploy in Pasay City only police officers and personnel who are residents of Pasay City for at least ONE (1) year prior to deployment; , \ WHEREAS, Notwithstanding the aforesaid resolution the PNP Directorate continue NW to assign and deploy police officers and personnel in the City who lack ONE (1) year N residency in Pasay City; SFY) WHEREAS, the City Government has been paying allowances to all police officers S&T /and personnel performing duties in Pasay City; WHEREAS, there is a need to enact rules and regulations in the payment of allowance to police officers and personnel to give teeth to Resolution No. 945; S-1997 so that its intention be satisfied and complied with; NOW THEREFORE, be it ORDAINED as it is hereby ORDAINED, in session duly assembled that: SECTION 1. ALLOWANCE - all police officers and personnel presently assigned and fe deployed in Pasay City shall be entitled to payment of existing allowance being provided by - the City Government, except those assigned and deployed after the effectively of this / | Ordinance and has not acquired ONE (1) year residing prior to assignment and deployment; / SECTION 2.- PROOF OF RESIDENCY - All police officers and personnel who ue ; assigned and deployed after the effectivity of this ordinance must show proof of residency) | consisting of Certification from the COMELEC of Pasay City and /or from the Barangay | Chairman of the place where the assignee is residing to be submitted to the Office of the \ 4 Mayor and Treasurer, respectively; < SECTION 3.-ACQUISITION OF ONE (1) YEAR RESIDENCY - AIl police officers and personnel assigned and deployed after the effetivity of this ordinance and who has not qualified for payment of the allowance, shall after ONE (1) year of continuos residency in Pasay City shall qualify for payment of existing allowances; SECTION 4.. AMENDMENT/REPEAL - Any existing ordinance or provision thereof inconsistent with any provision of this ordinance are hereby deemed amended or repealed; -Page 2- (Ordinance No. “ 1997) 8. 9. . Hon . Hon . Hon . Hon Hon Hon . Hon Hon Hon SECTION 5.- Any police officers and personnel assigned and deployed in Pasay City after the effectivity of this ordinance and who misrepresent himself to be a resident of Pasay City in order to qualify for payment of allowance being provided by the City and COMELEC personnel and Barangay Chairman who falsely certify to the required residency shall suffer the penalty of of ONE (1) year imprisonment; SECTION 6.- EFFECTIVITY - This ordinance shall take effect immediately upon its approval ; ENACTED in the City of Pasay this 3rd day of December in the Year of Our Lord Nineteen Hundred and Ninety Seven, APPROVED: HON. WENCESLAO B. TRINIDAD H Acting City Mayor Acting ee ES aa. \ v.+,°4 . ANTONINO G. CALIXTO Ba . EMMANUEL M. IBAY ~~ Yl ~-CjZ > , JUSTO C. JUSTO Ataaw . ROMULO M. CABRERA | ee et er , REYNALDO O. PADUA Ke ee “si . ROBERTO L. ALVAREZ . ba . EDITA V. VERGEL DE DIOS ,ULDRICO C. ARABIA ae _ ALBERTO V. PAREDES AY 10, Hon. EDUARDO I. ADVINCULA 11. Hon. TEOQDULO R. LORCA, JR. 12. Hon. GENEROSO F. CUNETA 13. Hon. LEVINE A, CUNETA ALTESTED: BY: ATTY. ROBER10 B. YAM City Secretary | D9: Pasay | E9: 0.47402597 | F9: 56.7826
